<?xml version="1.0" ?>
<robot name="robot_2" xmlns:xacro="http://www.ros.org/wiki/xacro">

<xacro:include filename="$(find robot_2_description)/urdf/materials.xacro" />
<xacro:include filename="$(find robot_2_description)/urdf/robot_2.trans" />
<xacro:include filename="$(find robot_2_description)/urdf/robot_2.gazebo" />
<xacro:include filename="$(find robot_2_description)/urdf/ros2_control.xacro" />
<xacro:include filename="$(find robot_2_description)/urdf/lidar.xacro" />
<xacro:include filename="$(find robot_2_description)/urdf/camera.xacro" />

<link name="base_link">
  <inertial>
    <origin xyz="-0.030778695710215853 -0.00017187958403205029 0.0780034263273014" rpy="0 0 0"/>
    <mass value="6.148868144226647"/>
    <inertia ixx="0.012471" iyy="0.038142" izz="0.040818" ixy="-6.8e-05" iyz="-2e-05" ixz="0.007561"/>
  </inertial>
  <visual>
    <origin xyz="0 0 0" rpy="0 0 3.141592653589793"/>
    <geometry>
      <mesh filename="file://$(find robot_2_description)/meshes/base_link.stl" scale="0.001 0.001 0.001"/>
    </geometry>
    <material name="silver"/>
  </visual>
  <collision>
    <origin xyz="0 0 0" rpy="0 0 3.141592653589793"/>
    <geometry>
      <mesh filename="file://$(find robot_2_description)/meshes/base_link.stl" scale="0.001 0.001 0.001"/>
    </geometry>
  </collision>
</link>

<link name="right_steering_1">
  <inertial>
    <origin xyz="0.006158363315530671 0.0020544276496725286 -3.3069679672426133e-06" rpy="0 0 0"/>
    <mass value="0.09920122832738423"/>
    <inertia ixx="9e-06" iyy="1.4e-05" izz="1.5e-05" ixy="1e-06" iyz="0.0" ixz="-0.0"/>
  </inertial>
  <visual>
    <origin xyz="-0.10312 0.0505 -0.0351" rpy="0 0 3.141592653589793"/>
    <geometry>
      <mesh filename="file://$(find robot_2_description)/meshes/right_steering_1.stl" scale="0.001 0.001 0.001"/>
    </geometry>
    <material name="silver"/>
  </visual>
  <collision>
    <origin xyz="-0.10312 0.0505 -0.0351" rpy="0 0 3.141592653589793"/>
    <geometry>
      <mesh filename="file://$(find robot_2_description)/meshes/right_steering_1.stl" scale="0.001 0.001 0.001"/>
    </geometry>
  </collision>
</link>

<link name="left_steering_1">
  <inertial>
    <origin xyz="0.006158363315530768 -0.0020544276496724106 3.3452641401351957e-06" rpy="0 0 0"/>
    <mass value="0.09920122832738423"/>
    <inertia ixx="9e-06" iyy="1.4e-05" izz="1.5e-05" ixy="-1e-06" iyz="0.0" ixz="0.0"/>
  </inertial>
  <visual>
    <origin xyz="-0.10312 -0.0505 -0.0351" rpy="0 0 3.141592653589793"/>
    <geometry>
      <mesh filename="file://$(find robot_2_description)/meshes/left_steering_1.stl" scale="0.001 0.001 0.001"/>
    </geometry>
    <material name="silver"/>
  </visual>
  <collision>
    <origin xyz="-0.10312 -0.0505 -0.0351" rpy="0 0 3.141592653589793"/>
    <geometry>
      <mesh filename="file://$(find robot_2_description)/meshes/left_steering_1.stl" scale="0.001 0.001 0.001"/>
    </geometry>
  </collision>
</link>

<link name="left_rear_wheel_1">
  <inertial>
    <origin xyz="-9.911240016202694e-08 -0.00032956138667881996 2.034739292333665e-08" rpy="0 0 0"/>
    <mass value="0.4967432663929975"/>
    <inertia ixx="0.000229" iyy="0.000365" izz="0.000229" ixy="0.0" iyz="-0.0" ixz="0.0"/>
  </inertial>
  <visual>
    <origin xyz="0.097623 -0.083 -0.0351" rpy="0 0 3.141592653589793"/>
    <geometry>
      <mesh filename="file://$(find robot_2_description)/meshes/left_rear_wheel_1.stl" scale="0.001 0.001 0.001"/>
    </geometry>
    <material name="silver"/>
  </visual>
  <collision>
    <origin xyz="0.097623 -0.083 -0.0351" rpy="0 0 3.141592653589793"/>
    <geometry>
      <mesh filename="file://$(find robot_2_description)/meshes/left_rear_wheel_1.stl" scale="0.001 0.001 0.001"/>
    </geometry>
  </collision>
</link>

<link name="right_rear_wheel_1">
  <inertial>
    <origin xyz="1.9532710547609522e-07 0.0003295613866789171 2.0491547063350435e-08" rpy="0 0 0"/>
    <mass value="0.49674326639299754"/>
    <inertia ixx="0.000229" iyy="0.000365" izz="0.000229" ixy="-0.0" iyz="0.0" ixz="-0.0"/>
  </inertial>
  <visual>
    <origin xyz="0.098035 0.083 -0.0351" rpy="0 0 3.141592653589793"/>
    <geometry>
      <mesh filename="file://$(find robot_2_description)/meshes/right_rear_wheel_1.stl" scale="0.001 0.001 0.001"/>
    </geometry>
    <material name="silver"/>
  </visual>
  <collision>
    <origin xyz="0.098035 0.083 -0.0351" rpy="0 0 3.141592653589793"/>
    <geometry>
      <mesh filename="file://$(find robot_2_description)/meshes/right_rear_wheel_1.stl" scale="0.001 0.001 0.001"/>
    </geometry>
  </collision>
</link>

<link name="right_front_wheel_1">
  <inertial>
    <origin xyz="0 0 0" rpy="0 0 0"/>
    <mass value="0.9046643177648892"/>
    <inertia ixx="0.000333" iyy="0.000481" izz="0.000333" ixy="0.0" iyz="0.0" ixz="0.0"/>
  </inertial>
  <visual>
    <origin xyz="-0.10005 0.082822 -0.0351" rpy="0 0 3.141592653589793"/>
    <geometry>
      <mesh filename="file://$(find robot_2_description)/meshes/right_front_wheel_1.stl" scale="0.001 0.001 0.001"/>
    </geometry>
    <material name="silver"/>
  </visual>
  <collision>
    <origin xyz="-0.10005 0.082822 -0.0351" rpy="0 0 3.141592653589793"/>
    <geometry>
      <mesh filename="file://$(find robot_2_description)/meshes/right_front_wheel_1.stl" scale="0.001 0.001 0.001"/>
    </geometry>
  </collision>
</link>

<link name="left_front_wheel_1">
  <inertial>
    <origin xyz="0 0 0" rpy="0 0 0"/>
    <mass value="0.9046643177648891"/>
    <inertia ixx="0.000333" iyy="0.000481" izz="0.000333" ixy="0.0" iyz="0.0" ixz="0.0"/>
  </inertial>
  <visual>
    <origin xyz="-0.10005 -0.082822 -0.0351" rpy="0 0 3.141592653589793"/>
    <geometry>
      <mesh filename="file://$(find robot_2_description)/meshes/left_front_wheel_1.stl" scale="0.001 0.001 0.001"/>
    </geometry>
    <material name="silver"/>
  </visual>
  <collision>
    <origin xyz="-0.10005 -0.082822 -0.0351" rpy="0 0 3.141592653589793"/>
    <geometry>
      <mesh filename="file://$(find robot_2_description)/meshes/left_front_wheel_1.stl" scale="0.001 0.001 0.001"/>
    </geometry>
  </collision>
</link>

<joint name="right_steering_to_base_link" type="revolute">
  <origin xyz="0.10312 -0.0505 0.0351" rpy="0 0 0"/>
  <parent link="base_link"/>
  <child link="right_steering_1"/>
  <axis xyz="0.0 0.0 1.0"/>
  <limit lower="-0.785" upper="0.785" effort="200.0" velocity="10.0"/>
</joint>

<joint name="left_steering_to_base_link" type="revolute">
  <origin xyz="0.10312 0.0505 0.0351" rpy="0 0 0"/>
  <parent link="base_link"/>
  <child link="left_steering_1"/>
  <axis xyz="0.0 0.0 1.0"/>
  <limit lower="-0.785" upper="0.785" effort="200.0" velocity="10.0"/>
</joint>

<joint name="left_rear_wheel_to_base_link" type="continuous">
  <origin xyz="-0.097623 0.083 0.0351" rpy="0 0 0"/>
  <parent link="base_link"/>
  <child link="left_rear_wheel_1"/>
  <axis xyz="0.0 1.0 0.0"/> </joint>

<joint name="right_rear_wheel_to_base_link" type="continuous">
  <origin xyz="-0.098035 -0.083 0.0351" rpy="0 0 0"/>
  <parent link="base_link"/>
  <child link="right_rear_wheel_1"/>
  <axis xyz="0.0 1.0 0.0"/>
</joint>

<joint name="right_front_wheel_to_right_steering" type="continuous">
  <origin xyz="-0.00307 -0.032322 0.0" rpy="0 0 0"/>
  <parent link="right_steering_1"/>
  <child link="right_front_wheel_1"/>
  <axis xyz="0.0 1.0 0.0"/>
</joint>

<joint name="left_front_wheel_to_left_steering" type="continuous">
  <origin xyz="-0.00307 0.032322 0.0" rpy="0 0 0"/>
  <parent link="left_steering_1"/>
  <child link="left_front_wheel_1"/>
  <axis xyz="0.0 1.0 0.0"/>
</joint>

</robot>